Watching for file changes with StatReloader
Watching for file changes with StatReloader
"GET / HTTP/1.1" 200 11418
"GET / HTTP/1.1" 200 11418
"GET /core/check-zip/?zip_code=110001 HTTP/1.1" 200 90
"GET /core/check-zip/?zip_code=110001 HTTP/1.1" 200 90
Internal Server Error: /
Traceback (most recent call last):
  File "/home/runner/.local/lib/python3.12/site-packages/django_redis/cache.py", line 29, in _decorator
    return method(self, *args, **kwargs)
           ^^^^^^^^^^^^^^^^^^^^^^^^^^^^^
  File "/home/runner/.local/lib/python3.12/site-packages/django_redis/cache.py", line 138, in has_key
    return self.client.has_key(*args, **kwargs)
           ^^^^^^^^^^^^^^^^^^^^^^^^^^^^^^^^^^^^
  File "/home/runner/.local/lib/python3.12/site-packages/django_redis/client/default.py", line 740, in has_key
    raise ConnectionInterrupted(connection=client) from e
django_redis.exceptions.ConnectionInterrupted: Redis ConnectionError: Error 111 connecting to localhost:6379. Connection refused.

During handling of the above exception, another exception occurred:

Traceback (most recent call last):
  File "/home/runner/.local/lib/python3.12/site-packages/django/core/handlers/exception.py", line 55, in inner
    response = get_response(request)
               ^^^^^^^^^^^^^^^^^^^^^
  File "/home/runner/.local/lib/python3.12/site-packages/django/utils/deprecation.py", line 136, in __call__
    response = self.process_response(request, response)
               ^^^^^^^^^^^^^^^^^^^^^^^^^^^^^^^^^^^^^^^^
  File "/home/runner/.local/lib/python3.12/site-packages/django/contrib/sessions/middleware.py", line 59, in process_response
    request.session.save()
  File "/home/runner/.local/lib/python3.12/site-packages/django/contrib/sessions/backends/cache.py", line 56, in save
    return self.create()
           ^^^^^^^^^^^^^
  File "/home/runner/.local/lib/python3.12/site-packages/django/contrib/sessions/backends/cache.py", line 42, in create
    self._session_key = self._get_new_session_key()
                        ^^^^^^^^^^^^^^^^^^^^^^^^^^^
  File "/home/runner/.local/lib/python3.12/site-packages/django/contrib/sessions/backends/base.py", line 150, in _get_new_session_key
    if not self.exists(session_key):
           ^^^^^^^^^^^^^^^^^^^^^^^^
  File "/home/runner/.local/lib/python3.12/site-packages/django/contrib/sessions/backends/cache.py", line 73, in exists
    bool(session_key) and (self.cache_key_prefix + session_key) in self._cache
                          ^^^^^^^^^^^^^^^^^^^^^^^^^^^^^^^^^^^^^^^^^^^^^^^^^^^^
  File "/home/runner/.local/lib/python3.12/site-packages/django/core/cache/backends/base.py", line 299, in __contains__
    return self.has_key(key)
           ^^^^^^^^^^^^^^^^^
  File "/home/runner/.local/lib/python3.12/site-packages/django_redis/cache.py", line 36, in _decorator
    raise e.__cause__  # noqa: B904
    ^^^^^^^^^^^^^^^^^
  File "/home/runner/.local/lib/python3.12/site-packages/django_redis/client/default.py", line 738, in has_key
    return client.exists(key) == 1
           ^^^^^^^^^^^^^^^^^^
  File "/home/runner/.local/lib/python3.12/site-packages/redis/commands/core.py", line 1736, in exists
    return self.execute_command("EXISTS", *names, keys=names)
           ^^^^^^^^^^^^^^^^^^^^^^^^^^^^^^^^^^^^^^^^^^^^^^^^^^
  File "/home/runner/.local/lib/python3.12/site-packages/redis/client.py", line 621, in execute_command
    return self._execute_command(*args, **options)
           ^^^^^^^^^^^^^^^^^^^^^^^^^^^^^^^^^^^^^^^
  File "/home/runner/.local/lib/python3.12/site-packages/redis/client.py", line 627, in _execute_command
    conn = self.connection or pool.get_connection()
                              ^^^^^^^^^^^^^^^^^^^^^
  File "/home/runner/.local/lib/python3.12/site-packages/redis/utils.py", line 195, in wrapper
    return func(*args, **kwargs)
           ^^^^^^^^^^^^^^^^^^^^^
  File "/home/runner/.local/lib/python3.12/site-packages/redis/connection.py", line 1533, in get_connection
    connection.connect()
  File "/home/runner/.local/lib/python3.12/site-packages/redis/connection.py", line 380, in connect
    self.connect_check_health(check_health=True)
  File "/home/runner/.local/lib/python3.12/site-packages/redis/connection.py", line 397, in connect_check_health
    raise ConnectionError(self._error_message(e))
redis.exceptions.ConnectionError: Error 111 connecting to localhost:6379. Connection refused.
Internal Server Error: /
Traceback (most recent call last):
  File "/home/runner/.local/lib/python3.12/site-packages/django_redis/cache.py", line 29, in _decorator
    return method(self, *args, **kwargs)
           ^^^^^^^^^^^^^^^^^^^^^^^^^^^^^
  File "/home/runner/.local/lib/python3.12/site-packages/django_redis/cache.py", line 138, in has_key
    return self.client.has_key(*args, **kwargs)
           ^^^^^^^^^^^^^^^^^^^^^^^^^^^^^^^^^^^^
  File "/home/runner/.local/lib/python3.12/site-packages/django_redis/client/default.py", line 740, in has_key
    raise ConnectionInterrupted(connection=client) from e
django_redis.exceptions.ConnectionInterrupted: Redis ConnectionError: Error 111 connecting to localhost:6379. Connection refused.

During handling of the above exception, another exception occurred:

Traceback (most recent call last):
  File "/home/runner/.local/lib/python3.12/site-packages/django/core/handlers/exception.py", line 55, in inner
    response = get_response(request)
               ^^^^^^^^^^^^^^^^^^^^^
  File "/home/runner/.local/lib/python3.12/site-packages/django/utils/deprecation.py", line 136, in __call__
    response = self.process_response(request, response)
               ^^^^^^^^^^^^^^^^^^^^^^^^^^^^^^^^^^^^^^^^
  File "/home/runner/.local/lib/python3.12/site-packages/django/contrib/sessions/middleware.py", line 59, in process_response
    request.session.save()
  File "/home/runner/.local/lib/python3.12/site-packages/django/contrib/sessions/backends/cache.py", line 56, in save
    return self.create()
           ^^^^^^^^^^^^^
  File "/home/runner/.local/lib/python3.12/site-packages/django/contrib/sessions/backends/cache.py", line 42, in create
    self._session_key = self._get_new_session_key()
                        ^^^^^^^^^^^^^^^^^^^^^^^^^^^
  File "/home/runner/.local/lib/python3.12/site-packages/django/contrib/sessions/backends/base.py", line 150, in _get_new_session_key
    if not self.exists(session_key):
           ^^^^^^^^^^^^^^^^^^^^^^^^
  File "/home/runner/.local/lib/python3.12/site-packages/django/contrib/sessions/backends/cache.py", line 73, in exists
    bool(session_key) and (self.cache_key_prefix + session_key) in self._cache
                          ^^^^^^^^^^^^^^^^^^^^^^^^^^^^^^^^^^^^^^^^^^^^^^^^^^^^
  File "/home/runner/.local/lib/python3.12/site-packages/django/core/cache/backends/base.py", line 299, in __contains__
    return self.has_key(key)
           ^^^^^^^^^^^^^^^^^
  File "/home/runner/.local/lib/python3.12/site-packages/django_redis/cache.py", line 36, in _decorator
    raise e.__cause__  # noqa: B904
    ^^^^^^^^^^^^^^^^^
  File "/home/runner/.local/lib/python3.12/site-packages/django_redis/client/default.py", line 738, in has_key
    return client.exists(key) == 1
           ^^^^^^^^^^^^^^^^^^
  File "/home/runner/.local/lib/python3.12/site-packages/redis/commands/core.py", line 1736, in exists
    return self.execute_command("EXISTS", *names, keys=names)
           ^^^^^^^^^^^^^^^^^^^^^^^^^^^^^^^^^^^^^^^^^^^^^^^^^^
  File "/home/runner/.local/lib/python3.12/site-packages/redis/client.py", line 621, in execute_command
    return self._execute_command(*args, **options)
           ^^^^^^^^^^^^^^^^^^^^^^^^^^^^^^^^^^^^^^^
  File "/home/runner/.local/lib/python3.12/site-packages/redis/client.py", line 627, in _execute_command
    conn = self.connection or pool.get_connection()
                              ^^^^^^^^^^^^^^^^^^^^^
  File "/home/runner/.local/lib/python3.12/site-packages/redis/utils.py", line 195, in wrapper
    return func(*args, **kwargs)
           ^^^^^^^^^^^^^^^^^^^^^
  File "/home/runner/.local/lib/python3.12/site-packages/redis/connection.py", line 1533, in get_connection
    connection.connect()
  File "/home/runner/.local/lib/python3.12/site-packages/redis/connection.py", line 380, in connect
    self.connect_check_health(check_health=True)
  File "/home/runner/.local/lib/python3.12/site-packages/redis/connection.py", line 397, in connect_check_health
    raise ConnectionError(self._error_message(e))
redis.exceptions.ConnectionError: Error 111 connecting to localhost:6379. Connection refused.
"POST / HTTP/1.1" 500 163311
"POST / HTTP/1.1" 500 163311
/home/runner/work/multi-store-ecommerce/multi-store-ecommerce/multistore_ecommerce/settings.py changed, reloading.
/home/runner/work/multi-store-ecommerce/multi-store-ecommerce/multistore_ecommerce/settings.py changed, reloading.
Watching for file changes with StatReloader
Watching for file changes with StatReloader
Watching for file changes with StatReloader
Watching for file changes with StatReloader
"GET / HTTP/1.1" 200 11418
"GET / HTTP/1.1" 200 11418
"GET /core/check-zip/?zip_code=110001 HTTP/1.1" 200 90
"GET /core/check-zip/?zip_code=110001 HTTP/1.1" 200 90
"POST / HTTP/1.1" 302 0
"POST / HTTP/1.1" 302 0
"GET /home/110001/ HTTP/1.1" 200 14350
"GET /home/110001/ HTTP/1.1" 200 14350
"GET / HTTP/1.1" 200 11966
"GET / HTTP/1.1" 200 11966
"GET /core/check-zip/?zip_code=110003 HTTP/1.1" 200 88
"GET /core/check-zip/?zip_code=110003 HTTP/1.1" 200 88
"POST / HTTP/1.1" 302 0
"POST / HTTP/1.1" 302 0
"GET /home/110003/ HTTP/1.1" 200 20201
"GET /home/110003/ HTTP/1.1" 200 20201
"GET /accounts/register/ HTTP/1.1" 200 12326
"GET /accounts/register/ HTTP/1.1" 200 12326
/home/runner/work/multi-store-ecommerce/multi-store-ecommerce/accounts/admin.py changed, reloading.
/home/runner/work/multi-store-ecommerce/multi-store-ecommerce/accounts/admin.py changed, reloading.
Watching for file changes with StatReloader
Watching for file changes with StatReloader
